<?xml version="1.0" ?>
<robot name="ingenuity">

  <link name="body">
    <origin rpy="0 0 0" xyz="0.0 0 0.5"/>
    <inertial>
      <origin rpy="0.0 0.0 0.0" xyz="0.0 0.0 0.0"/>
      <inertia ixx="1.8" ixy="0.0" ixz="0.0" iyy="1.8" iyz="0.0" izz="1.8"/>
      <mass value="10.0"/>
    </inertial>
    <visual>
      <geometry>
        <mesh filename="package://ingenuity_description/models/ingenuity/meshes/base_one_part.dae" scale="1 1 1"/>
      </geometry>
    </visual>
  </link>
  <link name="rod_1">

    <inertial>
      <origin rpy="0.0 0.0 0.0" xyz="0.0 0.0 0"/>
      <inertia ixx="0.012" ixy="0.0" ixz="0.0" iyy="0.012" iyz="0.0" izz="0.0012"/>
      <mass value="1.0"/>
    </inertial>
    <visual>
      <origin rpy="0 0 0" xyz="0 0 -0.5"/>
      <geometry>
        <mesh filename="package://ingenuity_description/models/ingenuity/meshes/rotor_blade_bottom.dae" scale="1 1 1"/>
      </geometry>
    </visual>
  </link>
  <link name="blade_1">
    <inertial>
      <origin rpy="0.0 0.0 0.0" xyz="0.0 0.5 0"/>
      <inertia ixx="0.0000465" ixy="0.0" ixz="0.0" iyy="0.0000006" iyz="0.0" izz="0.0000470"/>
      <mass value="0.01"/>
    </inertial>
  </link>
  <link name="blade_2">
    <inertial>
      <origin rpy="0.0 0.0 0.0" xyz="0.0 0.5 0"/>
      <inertia ixx="0.0000465" ixy="0.0" ixz="0.0" iyy="0.0000006" iyz="0.0" izz="0.0000470"/>
      <mass value="0.01"/>
    </inertial>
  </link>
  <joint name="rod_1_joint" type="revolute">
    <parent link="body"/>
    <child link="rod_1"/>
    <origin rpy="0.0 0.0 0.0" xyz="0.0 0.0 0.5"/>
    <axis xyz="0.0 0.0 -1.0"/>
    <limit lower="-1e16" upper="1e16" effort="1e5" velocity="5000"/>
    <dynamics damping="0.0001" friction="0.1"/>
  </joint>
  <joint name="blade_1_joint" type="fixed">
    <parent link="rod_1"/>
    <child link="blade_1"/>
    <origin rpy="0.0 0.0 0.0" xyz="0.0 -0.5 0.0"/>
  </joint>
  <joint name="blade_2_joint" type="fixed">
    <parent link="rod_1"/>
    <child link="blade_2"/>
    <origin rpy="0.0 0.0 0.0" xyz="0.0 0.5 0.0"/>
  </joint>
  <link name="rod_2">
    <origin rpy="0 0 0" xyz="0 0 1.75"/>
    <inertial>
      <origin rpy="0.0 0.0 0.0" xyz="0.0 0.0 0"/>
      <inertia ixx="0.012" ixy="0.0" ixz="0.0" iyy="0.012" iyz="0.0" izz="0.0012"/>
      <mass value="1.0"/>
    </inertial>
    <visual>
      <origin rpy="0 0 0" xyz="0 0 -0.5"/>
      <geometry>
        <mesh filename="package://ingenuity_description/models/ingenuity/meshes/rotor_blade_top.dae" scale="1 1 1"/>
      </geometry>
    </visual>
  </link>
  <link name="solar_panel">
    <origin rpy="0 0 0" xyz="0 0 0.5"/>
    <visual>
      <geometry>
        <mesh filename="package://ingenuity_description/models/ingenuity/meshes/solar_panel_one_part.dae" scale="1 1 1"/>
      </geometry>
    </visual>
  </link>
  <link name="blade_3">
    <origin rpy="0.0 0 0" xyz="0 0 2.0"/>
    <inertial>
      <origin rpy="0.0 0.0 0.0" xyz="0.0 0.5 0"/>
      <inertia ixx="0.0000465" ixy="0.0" ixz="0.0" iyy="0.0000006" iyz="0.0" izz="0.0000470"/>
      <mass value="0.01"/>
    </inertial>
  </link>
  <link name="blade_4">
    <origin rpy="0.0 0 3.141593" xyz="0 0 2.0"/>
    <inertial>
      <origin rpy="0.0 0.0 0.0" xyz="0.0 0.5 0"/>
      <inertia ixx="0.0000465" ixy="0.0" ixz="0.0" iyy="0.0000006" iyz="0.0" izz="0.0000470"/>
      <mass value="0.01"/>
    </inertial>
  </link>
  <joint name="rod_2_joint" type="revolute">
    <parent link="body"/>
    <child link="rod_2"/>
    <origin rpy="0.0 0.0 0.0" xyz="0.0 0.0 0.5"/>
    <axis xyz="0.0 0.0 1.0"/>
    <limit lower="-1e16" upper="1e16" effort="1e5" velocity="5000"/>
    <dynamics damping="0.0001" friction="0.1"/>
  </joint>
  <joint name="blade_3_joint" type="fixed">
    <parent link="rod_2"/>
    <child link="blade_3"/>
    <origin rpy="0.0 0.0 0.0" xyz="0.0 0.0 0.0"/>
  </joint>
  <joint name="blade_4_joint" type="fixed">
    <parent link="rod_2"/>
    <child link="blade_4"/>
    <origin rpy="0.0 0.0 0.0" xyz="0.0 0.0 0.0"/>
  </joint>
  <joint name="solar_panel_joint" type="fixed">
    <parent link="body"/>
    <child link="solar_panel"/>
    <origin rpy="0 0 0" xyz="0 0 0"/>
  </joint>
</robot>
