<?xml version="1.0" ?>
<sdf version='1.9'>

  <model name="ingenuity">
  
      <enable_wind>true</enable_wind>
      <pose>0 0 0 0 0 0</pose>
      <link name="body">
        <pose>0.0 0 0.5 0 0 0</pose>
        <inertial>
          <pose>0.0 0.0 0.0 0.0 0.0 0.0</pose>
          <inertia>
            <ixx>1.8</ixx>
            <ixy>0.0</ixy>
            <ixz>0.0</ixz>
            <iyy>1.8</iyy>
            <iyz>0.0</iyz>
            <izz>1.8</izz>
          </inertia>
          <mass>10.0</mass>
        </inertial>
        <collision name="collision">
          <geometry>
            <mesh>
              <scale>1 1 1</scale>
              <uri>model://ingenuity/meshes/base_one_part.dae</uri>
            </mesh>
           </geometry>
          <surface>
            <friction>
              <ode>
                <mu>0.1</mu>
                <mu2>0.1</mu2>
              </ode>
            </friction>
          </surface>
        </collision>
        <visual name="visual">
          <geometry>
            <mesh>
              <scale>1 1 1</scale>
              <uri>model://ingenuity/meshes/base_one_part.dae</uri>
            </mesh>
           </geometry>
        </visual>
        <sensor name="altimeter" type="altimeter">
          <always_on>1</always_on>
          <update_rate>30</update_rate>
          <visualize>true</visualize>
          <topic>altimeter</topic>
          <enable_metrics>true</enable_metrics>
          <altimeter>
            <vertical_position>
              <noise type="gaussian">
                <mean>0.01</mean>
                <stddev>0.01</stddev>
              </noise>
            </vertical_position>
            <vertical_velocity>
              <noise type="gaussian">
                <mean>0.2</mean>
                <stddev>0.1</stddev>
              </noise>
            </vertical_velocity>
          </altimeter>
        </sensor>
        <sensor name="camera" type="camera">
          <pose>0 0 0 0 1.5708 0</pose>
          <camera>
            <vertical_fov>1.047</vertical_fov>
            <image>
              <width>320</width>
              <height>240</height>
              <format>R8G8B8</format>
            </image>
            <clip>
              <near>0.1</near>
              <far>100</far>
            </clip>
          </camera>
          <always_on>1</always_on>
          <update_rate>30</update_rate>
          <visualize>true</visualize>
          <topic>camera</topic>
        </sensor>
          <sensor name="imu" type="imu">
          <always_on>1</always_on>
          <update_rate>100</update_rate>
          <visualize>true</visualize>
          <topic>imu</topic>
          <enable_metrics>true</enable_metrics>
        </sensor>
      </link>

      <link name="rod_1">
        <pose>0 0 1.25 0 0 0</pose>
        <inertial>
          <pose>0.0 0.0 0 0.0 0.0 0.0</pose>
          <inertia>
            <ixx>0.012</ixx>
            <ixy>0.0</ixy>
            <ixz>0.0</ixz>
            <iyy>0.012</iyy>
            <iyz>0.0</iyz>
            <izz>0.0012</izz>
          </inertia>
          <mass>1.0</mass>
        </inertial>
        <collision name="collision">
          <geometry>
            <box>
              <size>0.02 0.02 0.5</size>
            </box>
          </geometry>
        </collision>
        <visual name="visual">
          <pose> 0 0 -0.75 0 0 0</pose>
          <geometry>
            <mesh>
              <scale>1 1 1</scale>
              <uri>model://ingenuity/meshes/rotor_blade_bottom.dae</uri>
            </mesh>
           </geometry>
        </visual>
      </link>
      <link name="blade_1">
        <pose>0 0 1.5 0.0 0 0</pose>
        <inertial>
          <pose>0.0 0.5 0 0.0 0.0 0.0</pose>
          <inertia>
            <ixx>0.0000465</ixx>
            <ixy>0.0</ixy>
            <ixz>0.0</ixz>
            <iyy>0.0000006</iyy>
            <iyz>0.0</iyz>
            <izz>0.0000470</izz>
          </inertia>
          <mass>0.01</mass>
        </inertial>
        <collision name="collision">
          <pose>0.0 0.5 0 0.0 0.0 0.0</pose>
          <geometry>
            <box>
              <size>0.2 1.0 0.01</size>
            </box>
          </geometry>
        </collision>
        
      </link>
      <link name="blade_2">
        <pose>0 0 1.5 0.0 0 3.141593</pose>
        <inertial>
          <pose>0.0 0.5 0 0.0 0.0 0.0</pose>
          <inertia>
            <ixx>0.0000465</ixx>
            <ixy>0.0</ixy>
            <ixz>0.0</ixz>
            <iyy>0.0000006</iyy>
            <iyz>0.0</iyz>
            <izz>0.0000470</izz>
          </inertia>
          <mass>0.01</mass>
        </inertial>
        <collision name="collision">
          <pose>0.0 0.5 0 0.0 0.0 0.0</pose>
          <geometry>
            <box>
              <size>0.2 1.0 0.01</size>
            </box>
          </geometry>
        </collision>
      </link>
      <joint name="rod_1_joint" type="revolute">
        <parent>body</parent>
        <child>rod_1</child>
        <pose>0.0 0.0 0.0 0.0 0.0 0.0</pose>
        <axis>
          <limit>
            <lower>-1e16</lower>
            <upper>1e16</upper>
          </limit>
          <xyz>0.0 0.0 -1.0</xyz>
          <dynamics>
            <damping>0.0001</damping>
            <friction>0.1</friction>
          </dynamics>
        </axis>
        <physics>
          <ode>
            <cfm_damping>1</cfm_damping>
          </ode>
        </physics>
      </joint>
      <joint name="blade_1_joint" type="fixed">
        <parent>rod_1</parent>
        <child>blade_1</child>
        <pose>0.0 -0.5 0.0 0.0 0.0 0.0</pose>
      </joint>
      <joint name="blade_2_joint" type="fixed">
        <parent>rod_1</parent>
        <child>blade_2</child>
        <pose>0.0 0.5 0.0 0.0 0.0 0.0</pose>
      </joint>


     <!-- New Rod 2 -->
      <link name="rod_2">
        <pose>0 0 1.75 0 0 0</pose> <!-- Positioned above Rod 1 -->
        <inertial>
          <pose>0.0 0.0 0 0.0 0.0 0.0</pose>
          <inertia>
            <ixx>0.012</ixx>
            <ixy>0.0</ixy>
            <ixz>0.0</ixz>
            <iyy>0.012</iyy>
            <iyz>0.0</iyz>
            <izz>0.0012</izz>
          </inertia>
          <mass>1.0</mass>
        </inertial>
        <collision name="collision">
          <geometry>
            <box>
              <size>0.02 0.02 0.5</size>
            </box>
          </geometry>
        </collision>
        <visual name="visual">
          <pose> 0 0 -1.25 0 0 0 </pose>
 
          <geometry>
            <mesh>
              <scale>1 1 1</scale>
              <uri>model://ingenuity/meshes/rotor_blade_top.dae</uri>
            </mesh>
           </geometry>

        </visual>
      </link>

      <link name="solar_panel">
       <pose>0 0 0.5 0 0 0</pose>
          <visual name="visual">
          <geometry>
            <mesh>
              <scale>1 1 1</scale>
              <uri>model://ingenuity/meshes/solar_panel_one_part.dae</uri>
            </mesh>
           </geometry>
        </visual>
      </link>


      <!-- New Blade 3 -->
      <link name="blade_3">
        <pose>0 0 2.0 0.0 0 0</pose>
        <inertial>
          <pose>0.0 0.5 0 0.0 0.0 0.0</pose>
          <inertia>
            <ixx>0.0000465</ixx>
            <ixy>0.0</ixy>
            <ixz>0.0</ixz>
            <iyy>0.0000006</iyy>
            <iyz>0.0</iyz>
            <izz>0.0000470</izz>
          </inertia>
          <mass>0.01</mass>
        </inertial>
        <collision name="collision">
          <pose>0.0 0.5 0 0.0 0.0 0.0</pose>
          <geometry>
            <box>
              <size>0.2 1.0 0.01</size>
            </box>
          </geometry>
        </collision>

      </link>

      <!-- New Blade 4 -->
      <link name="blade_4">
        <pose>0 0 2.0 0.0 0 3.141593</pose>
        <inertial>
          <pose>0.0 0.5 0 0.0 0.0 0.0</pose>
          <inertia>
            <ixx>0.0000465</ixx>
            <ixy>0.0</ixy>
            <ixz>0.0</ixz>
            <iyy>0.0000006</iyy>
            <iyz>0.0</iyz>
            <izz>0.0000470</izz>
          </inertia>
          <mass>0.01</mass>
        </inertial>
        <collision name="collision">
          <pose>0.0 0.5 0 0.0 0.0 0.0</pose>
          <geometry>
            <box>
              <size>0.2 1.0 0.01</size>
            </box>
          </geometry>
        </collision>

      </link>

      <!-- Rod 2 Joint -->
      <joint name="rod_2_joint" type="revolute">
        <parent>body</parent>
        <child>rod_2</child>
        <pose>0.0 0.0 0.0 0.0 0.0 0.0</pose>
        <axis>
          <limit>
            <lower>-1e16</lower>
            <upper>1e16</upper>
          </limit>
          <xyz>0.0 0.0 1.0</xyz> <!-- Opposite to Rod 1 -->
          <dynamics>
            <damping>0.0001</damping>
            <friction>0.1</friction>
          </dynamics>
        </axis>
        <physics>
          <ode>
            <cfm_damping>1</cfm_damping>
          </ode>
        </physics>
      </joint>

      <!-- Blade 3 Joint -->
      <joint name="blade_3_joint" type="fixed">
        <parent>rod_2</parent>
        <child>blade_3</child>
        <pose>0.0 0.0 0.0 0.0 0.0 0.0</pose>
      </joint>

      <!-- Blade 4 Joint -->
      <joint name="blade_4_joint" type="fixed">
        <parent>rod_2</parent>
        <child>blade_4</child>
        <pose>0.0 0.0 0.0 0.0 0.0 0.0</pose>
      </joint>

      <joint name="solar_panel_joint" type="fixed">
        <parent>body</parent>
        <child>solar_panel</child>
        <pose>0 0 0 0 0 0</pose>
      </joint>

      <!-- Plugins for new blades -->
      <plugin
        filename="helicopter_flight_simulation"
        name="gz::sim::systems::HelicopterFlightSimulation">
        <a0>0.1</a0>
        <cla>0.1</cla>
        <cda>0.001</cda>
        <cma>0.0</cma>
        <cp>0.0 0.5 0</cp>
        <area>0.2</area>
        <air_density>0.024082</air_density>
        <forward>1 0 0</forward>
        <upward>0 0 -1</upward>
        <link_name>blade_3</link_name>
      </plugin>
      <plugin
        filename="helicopter_flight_simulation"
        name="gz::sim::systems::HelicopterFlightSimulation">
        <a0>0.1</a0>
        <cla>0.1</cla>
        <cda>0.001</cda>
        <cma>0.0</cma>
        <cp>0.0 0.5 0</cp>
        <area>0.2</area>
        <air_density>0.024082</air_density>
        <forward>1 0 0</forward>
        <upward>0 0 -1</upward>
        <link_name>blade_4</link_name>
      </plugin>

      <plugin
        filename="gz-sim-joint-state-publisher-system"
        name="gz::sim::systems::JointStatePublisher">
        <joint_name>rod_1_joint</joint_name>
        <joint_name>rod_2_joint</joint_name>        
      </plugin>

      <plugin
        filename="helicopter_flight_simulation"
        name="gz::sim::systems::HelicopterFlightSimulation">
        <a0>0.1</a0>
        <cla>0.1</cla>
        <cda>0.001</cda>
        <cma>0.0</cma>
        <cp>0.0 0.5 0</cp>
        <area>0.2</area>
        <air_density>0.024082</air_density>
        <forward>1 0 0</forward>
        <upward>0 0 1</upward>
        <link_name>blade_1</link_name>
      </plugin>
      <plugin
        filename="helicopter_flight_simulation"
        name="gz::sim::systems::HelicopterFlightSimulation">
        <a0>0.1</a0>
        <cla>0.1</cla>
        <cda>0.001</cda>
        <cma>0.0</cma>
        <cp>0.0 0.5 0</cp>
        <area>0.2</area>
        <air_density>0.024082</air_density>
        <forward>1 0 0</forward>
        <upward>0 0 1</upward>
        <link_name>blade_2</link_name>
      </plugin>


    <plugin
      filename="gz-sim-joint-controller-system"
      name="gz::sim::systems::JointController">
      <joint_name>rod_1_joint</joint_name>
      <use_force_commands>true</use_force_commands>
      <p_gain>1.0</p_gain>
      <i_gain>0.1</i_gain>
      <d_gain>0.0</d_gain>
      <initial_velocity>2000.0</initial_velocity> 
    </plugin>

    <plugin
      filename="gz-sim-joint-controller-system"
      name="gz::sim::systems::JointController">
      <joint_name>rod_2_joint</joint_name>
      <use_force_commands>true</use_force_commands>
      <p_gain>1.0</p_gain>
      <i_gain>0.1</i_gain>
      <d_gain>0.0</d_gain>
      <initial_velocity>2000.0</initial_velocity> 
    </plugin>

    <plugin
        filename="gz-sim-pose-publisher-system"
        name="gz::sim::systems::PosePublisher">
      <use_pose_vector_msg>true</use_pose_vector_msg>
      <publish_nested_model_pose>true</publish_nested_model_pose>
    </plugin>
    
    <plugin name="gz::sim::systems::HelicopterControl" filename="helicopter_flight_control">
      <kp_alt>0.027</kp_alt>
      <ki_alt>0.0005</ki_alt>
      <kd_alt>0.1</kd_alt>
      <desired_altitude>10.0</desired_altitude>
      <link_name>body</link_name>
    </plugin>

    <plugin filename="gz-sim-linearbatteryplugin-system"
      name="gz::sim::systems::LinearBatteryPlugin">
      <battery_name>ingenuity_battery</battery_name>
      <voltage>4.2</voltage>
      <open_circuit_voltage_constant_coef>4.2</open_circuit_voltage_constant_coef>
      <open_circuit_voltage_linear_coef>-2.0</open_circuit_voltage_linear_coef>
      <initial_charge>2.5</initial_charge>
      <capacity>2.5 </capacity>
      <resistance>0.07</resistance>
      <smooth_current_tau>2.0</smooth_current_tau>
      <enable_recharge>true</enable_recharge>
      <charging_time>3.0</charging_time>
      <power_load>2.1</power_load>
      <start_on_motion>true</start_on_motion>
      <fix_issue_225>true</fix_issue_225>
    </plugin>

    <!-- <plugin
      filename="gz-sim-wind-effects-system"
      name="gz::sim::systems::WindEffects">
      <force_approximation_scaling_factor>1</force_approximation_scaling_factor>
      <horizontal>
        <magnitude>
          <time_for_rise>1</time_for_rise>
          <sin>
            <amplitude_percent>0.05</amplitude_percent>
            <period>60</period>
          </sin>
          <noise type="gaussian">
           <mean>0</mean>
           <stddev>0.0002</stddev>
          </noise>
        </magnitude>
        <direction>
          <time_for_rise>30</time_for_rise>
          <sin>
            <amplitude>5</amplitude>
            <period>20</period>
          </sin>
          <noise type="gaussian">
           <mean>0</mean>
           <stddev>0.03</stddev>
          </noise>
        </direction>
      </horizontal>
      <vertical>
        <noise type="gaussian">
         <mean>0</mean>
         <stddev>0.03</stddev>
        </noise>
      </vertical>
    </plugin> -->

    </model>

</sdf>
